Workbook

Sheet README
A1: Fantasy Life 2027 — Draft Research
A2: Built 2026-10-22 for the Oct 25, 2026 draft. Regenerate: python3 draft_guide/build_workbook.py (data in draft_guide/data/*.json).
A4: How to read it
A5: Master = top-15 per category by expected league points (EV). Draft Board = every candidate across all 15 categories ranked by VOR.
A6: EV = E[rank points among the 13 drafted picks] (Monte Carlo on mu/sd) + E[bonus] (ladder × probabilities; live formula on the Assumptions tab).
A7: VOR = EV − EV of the replacement pick (Nth best in the category; N on Assumptions). Risk-adj VOR subtracts λ × SD of rank points.
A8: Yellow confidence cell = C (estimate) or ladder probabilities inferred from the title price. A = exchange/book price seen; B = article reporting odds.
A10: Timeline (league year 2027)
A11: NFL 2026 and NCAAF 2026 are in progress (current records matter); NBA/NHL/NCAAB 2026-27 are starting; MLB/MLS/NASCAR/Golf/Tennis/Stock/Actor/Actress/Musician/Country are calendar 2027.
A12: Oscars (Mar 2027) honour 2026 films and Grammys (Feb 2027) honour Aug 2025–Aug 2026 music → awards bonuses are priced from awards-season odds; Actor/Actress BASELINE uses 2027 releases.
A13: Country = IMF October 2026 WEO (published Oct 13) 2027 growth, pulled from api.imf.org — final for the draft.
A15: Assumptions to confirm
... A46: Refresh: see .claude/commands/fl-draft-prep.md — new prices go in draft_guide/raw/*.json, run kalshi_overlay.py, edit data/*.json, rebuild.

Sheet Master
A1: Top 15 (EV) → | B1: NFL | C1: NBA | D1: MLB | E1: NHL | F1: NCAAF | G1: NCAAB | H1: Tennis | I1: Golf | J1: NASCAR | K1: MLS | L1: Actor | M1: Actress | N1: Musician | O1: Country | P1: Stock
A2: #1 | B2: San Francisco 49ers Kalshi 9.5% · EV 17.6 · [Todd] | C2: Oklahoma City Thunder Kalshi 21.5% · EV 17.5 · [Feder] | D2: Los Angeles Dodgers · EV 12.7 · [Wu] | E2: Carolina Hurricanes Kalshi 9.5% · EV 13.9 · [Jamzee] | F2: Georgia Kalshi 16.5% · EV 16.9 · [Theo] | G2: Florida +600 · EV 14.9 · [Wu] | H2: Jannik Sinner +100 AO 2027 (pre-injury) · EV 11.5 · [Buckley] | I2: Scottie Scheffler · EV 11.7 · [Wu] | J2: Kyle Larson 2026 title: Kalshi 42.0% · EV 14.5 · [Molmen] | K2: Nashville SC 2026 Cup: Kalshi 18.0% · EV 10.1 | L2: Ryan Gosling · EV 9.6 | M2: Julianne Moore · EV 12.1 | N2: Ella Langley Grammy EV 10.8 (raw 12.8, P(cap) 50%) · EV 20.1 | O2: Iraq IMF Oct-2026 2027: 19.0% · EV 10.8 | P2: MSTR (Long) · EV 7.1
A3: #2 | B3: Kansas City Chiefs Kalshi 9.5% · EV 14.8 · [Shep] | C3: San Antonio Spurs Kalshi 21.5% · EV 15.8 · [Wu] | D3: Milwaukee Brewers · EV 11.6 · [Buckley] | E3: Tampa Bay Lightning Kalshi 5.5% · EV 13.4 · [Fryar] | F3: Notre Dame Kalshi 12.5% · EV 15.5 · [Feder] | G3: Duke +600 · EV 14.7 · [Jens] | H3: Elena Rybakina +300 AO 2027 · EV 10.8 | I3: Rory McIlroy · EV 11.1 · [Molmen] | J3: Denny Hamlin 2026 title: Kalshi 28.0% · EV 12.5 · [Theo] | K3: Vancouver Whitecaps FC 2026 Cup: Kalshi 23.5% · EV 10.1 · [Feder] | L3: John Malkovich · EV 9.2 | M3: Kristen Bell · EV 9.1 | N3: Olivia Rodrigo Grammy EV 9.4 (raw 10.3, P(cap) 31%) · EV 18.0 · [Todd] | O3: Qatar IMF Oct-2026 2027: 18.8% · EV 10.8 | P3: COIN (Long) · EV 7.1 · [Tim]
A4: #3 | B4: Buffalo Bills Kalshi 10.5% · EV 14.1 · [Jens] | C4: Philadelphia 76ers Kalshi 12.5% · EV 12.8 | D4: New York Yankees · EV 11.2 · [Jens] | E4: Edmonton Oilers Kalshi 8.5% · EV 13.1 · [Buckley] | F4: Miami (FL) Kalshi 14.5% · EV 15.4 · [Wu] | G4: UConn +1300 · EV 11.7 · [Fryar] | H4: Aryna Sabalenka +175 to +185 AO 2027 · EV 10.6 · [Fryar] | I4: Matt Fitzpatrick · EV 10.4 | J4: Christopher Bell 2026 title: Kalshi 10.5% · EV 11.2 · [Wu] | K4: Inter Miami CF 2026 Cup: Kalshi 16.5% · EV 9.3 · [Theo] | L4: Aaron Pierre · EV 9.1 | M4: Anne Hathaway · EV 8.0 · [Korch] | N4: Olivia Dean Grammy EV 8.5 (raw 9.2, P(cap) 23%) · EV 15.8 | O4: Guyana IMF Oct-2026 2027: 16.8% · EV 10.1 · [Korch] | P4: AMD (Long) · EV 7.1
A5: #4 | B5: Minnesota Vikings Kalshi 3.5% · EV 12.5 | C5: New York Knicks Kalshi 8.5% · EV 12.4 · [Buckley] | D5: Atlanta Braves · EV 10.5 · [Todd] | E5: Colorado Avalanche Kalshi 12.5% · EV 12.3 · [Korch] | F5: Ohio State Kalshi 12.5% · EV 15.1 · [Mitchell] | G5: Illinois +1300 · EV 11.7 | H5: Carlos Alcaraz +150 AO 2027 · EV 10.4 · [Todd] | I5: Cameron Young · EV 9.8 | J5: Joey Logano 2026 title: Kalshi 5.5% · EV 10.4 · [Jamzee] | K5: St. Louis City SC 2026 Cup: Kalshi 5.5% · EV 8.4 | L5: Skyler Gisondo · EV 8.9 | M5: Hailee Steinfeld · EV 7.4 | N5: Bruno Mars Grammy EV 7.0 (raw 7.3, P(cap) 11%) · EV 15.1 | O5: Kuwait IMF Oct-2026 2027: 17.1% · EV 10.1 | P5: TTWO (Long) · EV 7.1 · [Molmen]
A6: #5 | B6: Baltimore Ravens Kalshi 7.5% · EV 11.7 · [Wu] | C6: Minnesota Timberwolves Kalshi 6.5% · EV 11.2 · [Todd] | D6: Tampa Bay Rays · EV 10.4 | E6: Florida Panthers Kalshi 10.5% · EV 11.7 · [Todd] | F6: Texas Kalshi 3.5% · EV 12.3 | G6: Michigan +1600 · EV 10.9 · [Jamzee] | H6: Alexander Zverev +700 AO 2027 · EV 10.1 · [Theo] | I6: Wyndham Clark · EV 9.3 | J6: Ryan Blaney 2026 title: Kalshi 5.5% · EV 9.9 · [Fryar] | K6: FC Dallas 2026 Cup: Kalshi 4.5% · EV 8.4 | L6: Matt Damon · EV 7.7 · [Molmen] | M6: Lauren Vélez · EV 7.3 | N6: Taylor Swift Grammy EV 7.4 (raw 7.7, P(cap) 13%) · EV 15.1 · [Molmen] | O6: Sudan IMF Oct-2026 2027: 15.0% · EV 8.8 | P6: SMCI (Long) · EV 7.0 · [Korch]
A7: #6 | B7: Jacksonville Jaguars Kalshi 6.5% · EV 11.3 | C7: Boston Celtics Kalshi 4.5% · EV 10.9 · [Shep] | D7: Chicago Cubs · EV 9.9 · [Tim] | E7: Vegas Golden Knights Kalshi 7.5% · EV 10.8 · [Tim] | F7: Indiana Kalshi 7.5% · EV 11.9 · [Korch] | G7: Michigan State +2200 · EV 9.9 | H7: Jessica Pegula · EV 7.7 · [Korch] | I7: Russell Henley · EV 8.8 · [Jens] | J7: William Byron 2026 title: Kalshi 0.5% · EV 8.8 · [Korch] | K7: New England Revolution 2026 Cup: Kalshi 3.5% · EV 8.3 | L7: Andrew Scott · EV 7.1 | M7: Kimiko Glenn · EV 7.3 | N7: Rosalía Grammy EV 6.6 (raw 6.8, P(cap) 9%) · EV 11.2 | O7: Bahrain IMF Oct-2026 2027: 13.9% · EV 8.7 | P7: TSLA (Short) · EV 7.0 · [Shep]
A8: #7 | B8: Chicago Bears Kalshi 4.5% · EV 10.8 | C8: Toronto Raptors Kalshi 2.5% · EV 9.6 | D8: San Diego Padres · EV 9.9 · [Theo] | E8: Minnesota Wild Kalshi 6.5% · EV 10.6 | F8: Alabama Kalshi 4.5% · EV 10.7 · [Jamzee] | G8: Houston +2500 · EV 9.7 · [Theo] | H8: Ben Shelton · EV 7.5 | I8: Tommy Fleetwood · EV 8.4 · [Korch] | J8: Chase Briscoe 2026 title: Kalshi 3.5% · EV 7.1 · [Jens] | K8: Chicago Fire FC 2026 Cup: Kalshi 4.5% · EV 8.1 | L8: Josh Gad · EV 6.9 | M8: Adria Arjona · EV 7.2 | N8: Harry Styles Grammy EV 3.5 (raw 3.5, P(cap) 1%) · EV 10.7 | O8: Uganda IMF Oct-2026 2027: 9.9% · EV 6.8 | P8: RKLB (Long) · EV 7.0
A9: #8 | B9: Denver Broncos Kalshi 3.5% · EV 10.2 · [Molmen] | C9: Miami Heat Kalshi 6.5% · EV 9.5 | D9: Philadelphia Phillies · EV 9.9 · [Mitchell] | E9: Utah Mammoth Kalshi 3.0% · EV 9.9 | F9: BYU Kalshi 3.5% · EV 8.4 · [Tim] | G9: Arizona +2500 · EV 9.7 | H9: Coco Gauff · EV 7.5 · [Wu] | I9: Chris Gotterup · EV 7.9 | J9: Chase Elliott 2026 title: Kalshi 1.0% · EV 7.0 · [Todd] | K9: Los Angeles FC 2026 Cup: Kalshi 5.5% · EV 8.1 · [Buckley] | L9: Brian Tyree Henry · EV 6.9 | M9: Amy Adams · EV 6.9 | N9: Ariana Grande Grammy EV 2.7 (raw 2.7, P(cap) 0%) · EV 10.7 | O9: Saudi Arabia IMF Oct-2026 2027: 7.9% · EV 4.6 | P9: HOOD (Long) · EV 7.0
A10: #9 | B10: New England Patriots Kalshi 2.5% · EV 9.5 · [Feder] | C10: Los Angeles Lakers Kalshi 3.5% · EV 9.2 · [Theo] | D10: Boston Red Sox · EV 9.6 | E10: Washington Capitals Kalshi 5.5% · EV 9.5 · [Feder] | F10: Ole Miss Kalshi 4.5% · EV 8.2 · [Todd] | G10: Kansas +4000 · EV 7.7 · [Shep] | H10: Mirra Andreeva · EV 7.0 | I10: Sam Burns · EV 7.4 | J10: Tyler Reddick 2026 title: Kalshi 2.0% · EV 6.9 · [Feder] | K10: Houston Dynamo FC 2026 Cup: Kalshi 3.5% · EV 8.1 | L10: Matt Berry · EV 6.7 | M10: Inde Navarrette · EV 6.8 | N10: Raye Grammy EV 5.8 (raw 5.9, P(cap) 6%) · EV 10.4 | O10: Guinea IMF Oct-2026 2027: 7.8% · EV 4.4 · [Todd] | P10: TSLA (Long) · EV 7.0
A11: #10 | B11: Cincinnati Bengals Kalshi 3.5% · EV 9.4 | C11: Detroit Pistons +2200 · EV 9.0 | D11: Arizona Diamondbacks · EV 9.0 | E11: Dallas Stars Kalshi 5.5% · EV 9.1 · [Mitchell] | F11: LSU Kalshi 4.5% · EV 7.9 | G11: Kentucky · EV 7.4 · [Feder] | H11: Felix Auger-Aliassime · EV 6.7 | I11: Xander Schauffele · EV 6.9 · [Tim] | J11: Shane van Gisbergen 2026 title: Kalshi 0.5% · EV 6.7 · [Mitchell] | K11: San Jose Earthquakes 2026 Cup: Kalshi 2.5% · EV 8.1 | L11: Jake Johnson · EV 6.5 | M11: Mia Goth · EV 6.8 | N11: BTS Grammy EV 2.6 · EV 9.9 · [Theo] | O11: Ethiopia IMF Oct-2026 2027: 7.8% · EV 4.3 | P11: SOFI (Long) · EV 7.0 · [Jens]
A12: #11 | B12: Detroit Lions +3500 · EV 9.1 · [Jamzee] | C12: Denver Nuggets Kalshi 2.5% · EV 8.7 · [Tim] | D12: Cleveland Guardians · EV 8.8 · [Fryar] | E12: Boston Bruins Kalshi +9900 · EV 8.6 · [Shep] | F12: Oregon Kalshi 2.0% · EV 6.4 · [Buckley] | G12: Purdue +6500 · EV 6.6 · [Korch] | H12: Daniil Medvedev · EV 6.2 · [Molmen] | I12: Collin Morikawa · EV 6.5 · [Buckley] | J12: Michael McDowell 2026 title: Kalshi 0.5% · EV 6.6 | K12: Charlotte FC 2026 Cup: Kalshi 2.5% · EV 7.9 · [Tim] | L12: Shameik Moore · EV 6.5 | M12: Rachel Brosnahan · EV 6.6 | N12: Morgan Wallen Grammy EV 0.8 · EV 9.2 | O12: United Arab Emirates IMF Oct-2026 2027: 7.7% · EV 4.2 | P12: IONQ (Long) · EV 7.0
... A16: #15 | B16: Houston Texans +4500 · EV 6.7 | C16: Portland Trail Blazers · EV 7.1 | D16: New York Mets · EV 8.6 · [Feder] | E16: San Jose Sharks Kalshi 4.5% · EV 7.3 | F16: Tennessee Kalshi 1.5% · EV 4.2 | G16: Texas Tech · EV 6.4 | H16: Novak Djokovic +1600 AO 2027 · EV 5.1 · [Shep] | I16: Jon Rahm · EV 5.1 · [Shep] | J16: Riley Herbst 2026 title: Kalshi 0.5% · EV 6.6 | K16: Orlando City SC 2026 Cup: Kalshi 0.5% · EV 7.4 · [Shep] | L16: Daniel Kaluuya · EV 6.4 | M16: Milly Alcock · EV 6.5 | N16: Justin Bieber Grammy EV 0.3 · EV 7.6 · [Fryar] | O16: Rwanda IMF Oct-2026 2027: 7.2% · EV 3.6 | P16: LULU (Long) · EV 7.0 · [Wu]

Sheet Rosters
A1: Player | B1: NFL | C1: NBA | D1: MLB | E1: NHL | F1: NCAAF | G1: NCAAB | H1: Tennis | I1: Golf | J1: NASCAR | K1: MLS | L1: Actor | M1: Actress | N1: Musician | O1: Country | P1: Stock | Q1: Best keeper (by VOR)
A2: Tim | B2: Seattle Seahawks | C2: Denver Nuggets | D2: Chicago Cubs | E2: Vegas Golden Knights | F2: BYU | G2: St. John's | H2: Madison Keys | I2: Xander Schauffele | J2: Bubba Wallace | K2: Charlotte FC | L2: Sean Penn | M2: Ariana Grande | N2: Kendrick Lamar | O2: Netherlands | P2: COIN (Long) | Q2: Vegas Golden Knights (NHL, VOR 0.3)
A3: Wu | B3: Baltimore Ravens | C3: San Antonio Spurs | D3: Los Angeles Dodgers | E3: New Jersey Devils | F3: Miami (FL) | G3: Florida | H3: Coco Gauff | I3: Scottie Scheffler | J3: Christopher Bell | K3: Minnesota United FC | L3: Wagner Moura | M3: Zendaya | N3: FKA Twigs | O3: United States | P3: LULU (Long) | Q3: San Antonio Spurs (NBA, VOR 6.2)
A4: Jens | B4: Buffalo Bills | C4: Cleveland Cavaliers | D4: New York Yankees | E4: Toronto Maple Leafs | F4: Georgia Tech | G4: Duke | H4: Jasmine Paolini | I4: Russell Henley | J4: Chase Briscoe | K4: San Diego FC | L4: George Clooney | M4: Amanda Seyfried | N4: Sabrina Carpenter | O4: Germany | P4: SOFI (Long) | Q4: Duke (NCAAB, VOR 5.0)
A5: Todd | B5: San Francisco 49ers | C5: Minnesota Timberwolves | D5: Atlanta Braves | E5: Florida Panthers | F5: Ole Miss | G5: UCLA | H5: Carlos Alcaraz | I5: Patrick Cantlay | J5: Chase Elliott | K5: New York Red Bulls | L5: Leonardo DiCaprio | M5: Teyana Taylor | N5: Olivia Rodrigo | O5: Guinea | P5: NVDA (Long) | Q5: Olivia Rodrigo (Musician, VOR 7.3)
A6: Mitchell | B6: Los Angeles Rams | C6: Golden State Warriors | D6: Philadelphia Phillies | E6: Dallas Stars | F6: Ohio State | G6: Alabama | H6: Taylor Fritz | I6: J.J. Spaun | J6: Shane van Gisbergen | K6: Philadelphia Union | L6: Pedro Pascal | M6: Charlize Theron | N6: Bad Bunny | O6: South Sudan | P6: CVNA (Short) | Q6: Ohio State (NCAAF, VOR 4.4)
A7: Shep | B7: Kansas City Chiefs | C7: Boston Celtics | D7: Houston Astros | E7: Boston Bruins | F7: Michigan | G7: Kansas | H7: Novak Djokovic | I7: Jon Rahm | J7: Daniel Suarez | K7: Orlando City SC | L7: Jeremy Allen White | M7: Tessa Thompson | N7: Drake | O7: France | P7: TSLA (Short) | Q7: Kansas City Chiefs (NFL, VOR 4.0)
A8: Theo | B8: Indianapolis Colts | C8: Los Angeles Lakers | D8: San Diego Padres | E8: Detroit Red Wings | F8: Georgia | G8: Houston | H8: Alexander Zverev | I8: Justin Thomas | J8: Denny Hamlin | K8: Inter Miami CF | L8: Dwayne Johnson | M8: Sydney Sweeney | N8: BTS | O8: Switzerland | P8: CMG (Long) | Q8: Georgia (NCAAF, VOR 6.2)
A9: Feder | B9: New England Patriots | C9: Oklahoma City Thunder | D9: New York Mets | E9: Washington Capitals | F9: Notre Dame | G9: Kentucky | H9: Iga Swiatek | I9: Bryson DeChambeau | J9: Tyler Reddick | K9: Vancouver Whitecaps FC | L9: Tom Holland | M9: Cynthia Erivo | N9: Lady Gaga | O9: Brazil | P9: PLTR (Long) | Q9: Oklahoma City Thunder (NBA, VOR 7.9)
A10: Fryar | B10: Green Bay Packers | C10: Los Angeles Clippers | D10: Cleveland Guardians | E10: Tampa Bay Lightning | F10: Texas A&M | G10: UConn | H10: Aryna Sabalenka | I10: Viktor Hovland | J10: Ryan Blaney | K10: Columbus Crew | L10: Chris Hemsworth | M10: Florence Pugh | N10: Justin Bieber | O10: Norway | P10: AVGO (Long) | Q10: Aryna Sabalenka (Tennis, VOR 3.0)
A11: Korch | B11: Philadelphia Eagles | C11: Houston Rockets | D11: Toronto Blue Jays | E11: Colorado Avalanche | F11: Indiana | G11: Purdue | H11: Jessica Pegula | I11: Tommy Fleetwood | J11: William Byron | K11: FC Cincinnati | L11: Jon Bernthal | M11: Anne Hathaway | N11: SZA | O11: Guyana | P11: SMCI (Long) | Q11: Guyana (Country, VOR 3.3)
A12: Molmen | B12: Denver Broncos | C12: Milwaukee Bucks | D12: Texas Rangers | E12: New York Rangers | F12: Texas Tech | G12: North Carolina | H12: Daniil Medvedev | I12: Rory McIlroy | J12: Kyle Larson | K12: LA Galaxy | L12: Matt Damon | M12: Jessie Buckley | N12: Taylor Swift | O12: Argentina | P12: TTWO (Long) | Q12: Kyle Larson (NASCAR, VOR 7.5)
... A14: Buckley | B14: Tampa Bay Buccaneers | C14: New York Knicks | D14: Milwaukee Brewers | E14: Edmonton Oilers | F14: Oregon | G14: Louisville | H14: Jannik Sinner | I14: Collin Morikawa | J14: Ross Chastain | K14: Los Angeles FC | L14: Robert Pattinson | M14: Anya Taylor-Joy | N14: Beyoncé | O14: Canada | P14: NEE (Long) | Q14: Jannik Sinner (Tennis, VOR 4.0)
A15: Source: data/rosters.json (2026-league draft). Gold = that player's highest-VOR pick (keeper candidate). Keeper rules not modelled: owned players stay ranked on the board.
A16: Value over replacement (VOR) of each current pick — live link to the category tabs
A17: Tim | B17: ='NFL'!N16 | C17: ='NBA'!N15 | D17: ='MLB'!N10 | E17: ='NHL'!N10 | F17: ='NCAAF'!N12 | G17: ='NCAAB'!N26 | H17: ='Tennis'!N29 | I17: ='Golf'!N14 | J17: ='NASCAR'!N23 | K17: ='MLS'!N15 | L17: ='Actor'!N97 | M17: ='Actress'!N92 | N17: ='Musician'!N21 | O17: ='Country'!N61 | P17: ='Stock'!N6
A18: Wu | B18: ='NFL'!N9 | C18: ='NBA'!N6 | D18: ='MLB'!N5 | E18: ='NHL'!N17 | F18: ='NCAAF'!N7 | G18: ='NCAAB'!N5 | H18: ='Tennis'!N12 | I18: ='Golf'!N5 | J18: ='NASCAR'!N7 | K18: ='MLS'!N26 | L18: ='Actor'!N88 | M18: ='Actress'!N21 | N18: ='Musician'!N34 | O18: ='Country'!N57 | P18: ='Stock'!N19
A19: Jens | B19: ='NFL'!N7 | C19: ='NBA'!N18 | D19: ='MLB'!N7 | E19: ='NHL'!N23 | F19: ='NCAAF'!N28 | G19: ='NCAAB'!N6 | H19: ='Tennis'!N28 | I19: ='Golf'!N10 | J19: ='NASCAR'!N11 | K19: ='MLS'!N24 | L19: ='Actor'!N93 | M19: ='Actress'!N22 | N19: ='Musician'!N22 | O19: ='Country'!N63 | P19: ='Stock'!N14
A20: Todd | B20: ='NFL'!N5 | C20: ='NBA'!N9 | D20: ='MLB'!N8 | E20: ='NHL'!N9 | F20: ='NCAAF'!N13 | G20: ='NCAAB'!N34 | H20: ='Tennis'!N8 | I20: ='Golf'!N32 | J20: ='NASCAR'!N12 | K20: ='MLS'!N21 | L20: ='Actor'!N95 | M20: ='Actress'!N89 | N20: ='Musician'!N6 | O20: ='Country'!N13 | P20: ='Stock'!N22
A21: Mitchell | B21: ='NFL'!N18 | C21: ='NBA'!N27 | D21: ='MLB'!N12 | E21: ='NHL'!N14 | F21: ='NCAAF'!N8 | G21: ='NCAAB'!N18 | H21: ='Tennis'!N26 | I21: ='Golf'!N16 | J21: ='NASCAR'!N14 | K21: ='MLS'!N16 | L21: ='Actor'!N64 | M21: ='Actress'!N90 | N21: ='Musician'!N17 | O21: ='Country'!N18 | P21: ='Stock'!N18
A22: Shep | B22: ='NFL'!N6 | C22: ='NBA'!N10 | D22: ='MLB'!N20 | E22: ='NHL'!N15 | F22: ='NCAAF'!N25 | G22: ='NCAAB'!N13 | H22: ='Tennis'!N19 | I22: ='Golf'!N19 | J22: ='NASCAR'!N27 | K22: ='MLS'!N19 | L22: ='Actor'!N92 | M22: ='Actress'!N87 | N22: ='Musician'!N16 | O22: ='Country'!N65 | P22: ='Stock'!N10
A23: Theo | B23: ='NFL'!N30 | C23: ='NBA'!N13 | D23: ='MLB'!N11 | E23: ='NHL'!N34 | F23: ='NCAAF'!N5 | G23: ='NCAAB'!N11 | H23: ='Tennis'!N9 | I23: ='Golf'!N31 | J23: ='NASCAR'!N6 | K23: ='MLS'!N7 | L23: ='Actor'!N96 | M23: ='Actress'!N84 | N23: ='Musician'!N14 | O23: ='Country'!N64 | P23: ='Stock'!N23
A24: Feder | B24: ='NFL'!N13 | C24: ='NBA'!N5 | D24: ='MLB'!N19 | E24: ='NHL'!N13 | F24: ='NCAAF'!N6 | G24: ='NCAAB'!N14 | H24: ='Tennis'!N20 | I24: ='Golf'!N41 | J24: ='NASCAR'!N13 | K24: ='MLS'!N6 | L24: ='Actor'!N89 | M24: ='Actress'!N54 | N24: ='Musician'!N25 | O24: ='Country'!N59 | P24: ='Stock'!N27
A25: Fryar | B25: ='NFL'!N17 | C25: ='NBA'!N29 | D25: ='MLB'!N15 | E25: ='NHL'!N6 | F25: ='NCAAF'!N27 | G25: ='NCAAB'!N7 | H25: ='Tennis'!N7 | I25: ='Golf'!N17 | J25: ='NASCAR'!N9 | K25: ='MLS'!N30 | L25: ='Actor'!N94 | M25: ='Actress'!N88 | N25: ='Musician'!N19 | O25: ='Country'!N62 | P25: ='Stock'!N29
A26: Korch | B26: ='NFL'!N29 | C26: ='NBA'!N16 | D26: ='MLB'!N17 | E26: ='NHL'!N8 | F26: ='NCAAF'!N10 | G26: ='NCAAB'!N15 | H26: ='Tennis'!N10 | I26: ='Golf'!N11 | J26: ='NASCAR'!N10 | K26: ='MLS'!N23 | L26: ='Actor'!N98 | M26: ='Actress'!N7 | N26: ='Musician'!N24 | O26: ='Country'!N7 | P26: ='Stock'!N9
A27: Molmen | B27: ='NFL'!N12 | C27: ='NBA'!N33 | D27: ='MLB'!N22 | E27: ='NHL'!N22 | F27: ='NCAAF'!N16 | G27: ='NCAAB'!N24 | H27: ='Tennis'!N15 | I27: ='Golf'!N6 | J27: ='NASCAR'!N5 | K27: ='MLS'!N18 | L27: ='Actor'!N9 | M27: ='Actress'!N91 | N27: ='Musician'!N9 | O27: ='Country'!N56 | P27: ='Stock'!N8
A28: Jamzee | B28: ='NFL'!N15 | C28: ='NBA'!N22 | D28: ='MLB'!N23 | E28: ='NHL'!N5 | F28: ='NCAAF'!N11 | G28: ='NCAAB'!N9 | H28: ='Tennis'!N27 | I28: ='Golf'!N22 | J28: ='NASCAR'!N8 | K28: ='MLS'!N17 | L28: ='Actor'!N67 | M28: ='Actress'!N64 | N28: ='Musician'!N23 | O28: ='Country'!N60 | P28: ='Stock'!N26
A29: Buckley | B29: ='NFL'!N32 | C29: ='NBA'!N8 | D29: ='MLB'!N6 | E29: ='NHL'!N7 | F29: ='NCAAF'!N15 | G29: ='NCAAB'!N16 | H29: ='Tennis'!N5 | I29: ='Golf'!N15 | J29: ='NASCAR'!N20 | K29: ='MLS'!N12 | L29: ='Actor'!N41 | M29: ='Actress'!N41 | N29: ='Musician'!N26 | O29: ='Country'!N58 | P29: ='Stock'!N30

Sheet My Draft (slot 13)
A1: Korch — 2027 draft plan from the last slot
A2: Korch picks 13th (last) in every odd round and 1st in every even round; the keeper round also runs in draft order, so with no keeper the first three picks are back-to-back (keeper-round #13, R1 #13, R2 #14). Later pairs: 39/40, 65/66, 91/92, 117/118, 143/144, 169/170.
A3: Simulated 80 drafts per option (draft_sim.py, as of 2026-10-22). Assumed order: Shep, Jens, Todd, Feder, Tim, Molmen, Theo, Buckley, Mitchell, Jamzee, Fryar, Wu, Korch
A5: 1. Keep or draft? Recommendation: NO KEEPER
A6: Option | B6: Expected 2027 EV (dropoff drafting) | C6: SD | D6: Expected EV (best-available drafting)
A7: No keeper | B7: 157.5 | C7: 3.1 | D7: 154.9
A8: Keep Colorado Avalanche | B8: 152.9 | C8: 3.5 | D8: 150.3
A9: Keep Indiana | B9: 152.1 | C9: 2.7 | D9: 148.8
A10: Keep Guyana | B10: 151.5 | C10: 3.3 | D10: 150
A11: No keeper wins in the simulation (157.5 vs 152.9 keeping the Avalanche, 152.1 Indiana, 151.5 Guyana; sd ~3). Keeping uses the keeper-round pick on a player you could replace later; not keeping turns it into a free pick at #13, right before your R1/R2 turn.
A12: The Avalanche slid to 12.3 (4th in NHL) behind the Hurricanes 13.9, Lightning 13.4 and Oilers 13.1 (Oct 22 refresh). The sim now has Jamzee keeping Carolina and Fryar keeping Tampa Bay, so NHL thins out, but Golden Knights 10.8, Panthers 11.7 (Todd keeps Rodrigo) and Wild 10.6 still last to about R5. Keeping Colorado costs ~4.6 pts vs a free premium pick.
A13: Guyana is no longer the clear #1 Country: the IMF October 2026 WEO puts Iraq (19.0%), Qatar (18.8%) and Kuwait (17.1%) ahead of it for 2027 (16.8%), with Sudan 15.0% and Bahrain 13.9% close behind. Six live options, and Country goes late (median R10).
A14: What usually falls to #13 in the keeper round (Oct 22 refresh): the San Francisco 49ers (NFL #1, 17.6; Kalshi Super Bowl price now 17.5%). Todd owns them but keeps Rodrigo. Otherwise a top Musician (Langley 20.1 / Dean 15.8, both unowned). NCAAF goes at R1/R2: Texas fell again to 12.3 (title 3.5%), so Notre Dame 15.5 / Miami 15.4 are the targets if their owners keep elsewhere.
A16: 2. Round by round (no keeper, dropoff drafting): how often each category is the right pick, and who it usually is
A17: Round | B17: Overall pick | C17: Most common pick | D17: Also | E17: Also
A18: Keeper | B18: keeper rd #13 | C18: NFL 80% (San Francisco 49ers, Denver Broncos) | D18: Musician 20% (Morgan Wallen, BTS)
A19: R1 | B19: 13 | C19: NCAAB 41% (Florida, UConn) | D19: NCAAF 36% (Texas, Notre Dame) | E19: NASCAR 21% (Kyle Larson, Denny Hamlin)
A20: R2 | B20: 14 | C20: NCAAF 64% (Texas, Notre Dame) | D20: NCAAB 21% (Florida, UConn) | E20: NBA 5% (Minnesota Timberwolves, Boston Celtics)
A21: R3 | B21: 39 | C21: NASCAR 70% (Kyle Larson, Denny Hamlin) | D21: MLB 10% (Los Angeles Dodgers, Chicago Cubs) | E21: NCAAB 7% (Florida, UConn)
A22: R4 | B22: 40 | C22: NBA 39% (Minnesota Timberwolves, Boston Celtics) | D22: MLB 17% (Los Angeles Dodgers, Chicago Cubs) | E22: Golf 15% (Russell Henley, Xander Schauffele)
A23: R5 | B23: 65 | C23: NHL 38% (Vegas Golden Knights, Minnesota Wild) | D23: Tennis 23% (Elena Rybakina, Aryna Sabalenka) | E23: Country 7% (Sudan, Guyana)
A24: R6 | B24: 66 | C24: MLS 28% (Nashville SC, St. Louis City SC) | D24: NHL 24% (Vegas Golden Knights, Minnesota Wild) | E24: Tennis 16% (Elena Rybakina, Aryna Sabalenka)
A25: R7 | B25: 91 | C25: MLB 35% (Los Angeles Dodgers, Chicago Cubs) | D25: Musician 26% (Morgan Wallen, BTS) | E25: Country 12% (Sudan, Guyana)
A26: R8 | B26: 92 | C26: Country 56% (Sudan, Guyana) | D26: Golf 26% (Russell Henley, Xander Schauffele) | E26: Musician 6% (Morgan Wallen, BTS)
A27: R9 | B27: 117 | C27: Musician 28% (Morgan Wallen, BTS) | D27: NBA 25% (Minnesota Timberwolves, Boston Celtics) | E27: MLB 17% (Los Angeles Dodgers, Chicago Cubs)
A28: R10 | B28: 118 | C28: MLS 30% (Nashville SC, St. Louis City SC) | D28: Actor 19% (Josh Gad, Aaron Pierre) | E28: Musician 11% (Morgan Wallen, BTS)
A29: R11 | B29: 143 | C29: Actress 33% (Hailee Steinfeld, Lauren Vélez) | D29: MLS 26% (Nashville SC, St. Louis City SC) | E29: Tennis 17% (Elena Rybakina, Aryna Sabalenka)
A30: R12 | B30: 144 | C30: Actress 41% (Hailee Steinfeld, Lauren Vélez) | D30: Golf 20% (Russell Henley, Xander Schauffele) | E30: Tennis 17% (Elena Rybakina, Aryna Sabalenka)
... A32: R14 | B32: 170 | C32: Actor 53% (Josh Gad, Aaron Pierre) | D32: Golf 17% (Russell Henley, Xander Schauffele) | E32: Stock 14% (MSTR (Long), COIN (Long))
A33: Names in brackets are the players you most often end up with in that category across all rounds (for the keeper-round Musician case that means the best one left: Langley/Dean/Mars if they are still there).
A34: Rule of thumb: take the scarce team categories (NCAAF, NCAAB, NBA, NFL) at your early turns; let NASCAR, MLS, Actor, Actress and Stock come to you — the field ignores them until the middle or the end.
A36: 3. Value picks
A37: NASCAR | B37: Kyle Larson / Denny Hamlin | C37: #1/#2 NASCAR (14.5 / 12.5). Nobody drafted NASCAR before pick 63 last year; in the sim Larson is still there at your R1/R3 turn most of the time.
A38: NCAAF | B38: Notre Dame / Miami (FL), then Texas | C38: Notre Dame 15.5 (Feder keeps OKC) and Miami 15.4 (Wu keeps the Spurs) are the realistic R1/R2 targets; Texas (12.3, unowned) is the fallback after its title odds fell to 3.5%.
A39: NCAAB | B39: Florida | C39: #1 NCAAB (14.9). Wu owns it but should keep the Spurs instead.
A40: NBA | B40: Philadelphia 76ers | C40: #3 NBA (12.8), unowned. NBA gets stripped fast; this is the realistic upside after OKC/SAS are kept.
A41: NFL | B41: San Francisco 49ers, then Vikings / Jaguars | C41: 49ers 17.6 (NFL #1; Todd keeps Rodrigo, so the 49ers are in the pool) = keeper-round target. Fallback: Vikings 12.5 / Jaguars 11.3, unowned, last to about R5.
A42: NHL | B42: Golden Knights / Panthers / Wild | C42: 10.6-11.7 EV and last to about R5; Carolina and Tampa Bay are likely kept.
A43: Tennis | B43: Elena Rybakina | C43: #2 Tennis (10.8), unowned. Tennis is overpriced early, so wait and take what is left.
A44: Golf | B44: Matt Fitzpatrick / Cameron Young | C44: Unowned 9.8-10.4 EV. Golf is overpriced early.
...

Sheet Draft Plan
A1: Category | B1: 2026: 1st pick # | C1: 2026: median rd | D1: 2026: gone by R2 / R4 / R7 | E1: 2026: avg projected final | F1: 2026: surplus vs slot | G1: 2027 best EV | H1: EV left @R2 | I1: EV left @R4 | J1: EV left @R7 | K1: Cost to wait: R2 | L1: R4 | M1: R7 | N1: Free until round (<=1 pt) | O1: Read
A2: NFL | B2: 9 | C2: 3 | D2: 7 / 10 / 10 | E2: 10.7 | F2: -1 | G2: 17.6 | H2: 10.2 | I2: 9.1 | J2: 9.1 | K2: 7.4 | L2: 8.5 | M2: 8.5 | N2: 0 | O2: TAKE EARLY (R1-2): by R1 the field has taken 5 and the best left is 11.3 vs 17.6
A3: NBA | B3: 1 | C3: 4 | D3: 4 / 9 / 11 | E3: 11.1 | F3: -0.2 | G3: 17.5 | H3: 11.2 | I3: 9 | J3: 8.4 | K3: 6.2 | L3: 8.5 | M3: 9.1 | N3: 0 | O3: TAKE EARLY (R1-2): by R1 the field has taken 4 and the best left is 11.2 vs 17.5
A4: MLB | B4: 30 | C4: 6 | D4: 1 / 4 / 8 | E4: 10.4 | F4: 0.8 | G4: 12.7 | H4: 11.6 | I4: 10.4 | J4: 9.6 | K4: 1.2 | L4: 2.3 | M4: 3.2 | N4: 0 | O4: FLEXIBLE: within 1 pt through R0; by R5 you still get most of it
A5: NHL | B5: 4 | C5: 7 | D5: 4 / 6 / 8 | E5: 10 | F5: -0.6 | G5: 13.9 | H5: 11.7 | I5: 10.6 | J5: 9.5 | K5: 2.2 | L5: 3.3 | M5: 4.4 | N5: 1 | O5: TAKE BY R2: from R3 the best left drops 3+ pts below the top
A6: NCAAF | B6: 14 | C6: 3 | D6: 7 / 9 / 10 | E6: 11.1 | F6: -0.1 | G6: 16.9 | H6: 8.4 | I6: 7.9 | J6: 6.4 | K6: 8.5 | L6: 9 | M6: 10.4 | N6: 0 | O6: TAKE EARLY (R1-2): by R2 the field has taken 7 and the best left is 8.4 vs 16.9
A7: NCAAB | B7: 24 | C7: 7 | D7: 2 / 6 / 9 | E7: 10.3 | F7: 0.1 | G7: 14.9 | H7: 11.7 | I7: 9.7 | J7: 7.4 | K7: 3.2 | L7: 5.2 | M7: 7.5 | N7: 1 | O7: TAKE EARLY (R1-2): by R2 the field has taken 2 and the best left is 11.7 vs 14.9
A8: Tennis | B8: 6 | C8: 6 | D8: 7 / 8 / 10 | E8: 9 | F8: -2.9 | G8: 11.5 | H8: 7.5 | I8: 7 | J8: 6.2 | K8: 4 | L8: 4.5 | M8: 5.4 | N8: 0 | O8: TAKE EARLY (R1-2): by R1 the field has taken 7 and the best left is 7.5 vs 11.5
A9: Golf | B9: 2 | C9: 7 | D9: 2 / 3 / 7 | E9: 7.8 | F9: -1.8 | G9: 11.7 | H9: 10.4 | I9: 9.8 | J9: 7.9 | K9: 1.3 | L9: 1.9 | M9: 3.8 | N9: 1 | O9: FLEXIBLE: within 1 pt through R1; by R5 you still get most of it
A10: NASCAR | B10: 63 | C10: 8 | D10: 0 / 0 / 6 | E10: 9.7 | F10: 0.8 | G10: 14.5 | H10: 14.5 | I10: 14.5 | J10: 7.1 | K10: 0 | L10: 0 | M10: 7.5 | N10: 4 | O10: WAIT: the field leaves it alone until ~R5; the best player is free through R4
A11: MLS | B11: 31 | C11: 10 | D11: 0 / 1 / 5 | E11: 9.7 | F11: 1.3 | G11: 10.1 | H11: 10.1 | I11: 10.1 | J11: 8.3 | K11: 0 | L11: 0.1 | M11: 1.9 | N11: 6 | O11: WAIT: the field leaves it alone until ~R7; the best player is free through R6
A12: Actor | B12: 38 | C12: 8 | D12: 0 / 1 / 5 | E12: 8.6 | F12: -0.6 | G12: 9.6 | H12: 9.6 | I12: 9.2 | J12: 7.1 | K12: 0 | L12: 0.4 | M12: 2.6 | N12: 4 | O12: WAIT: the field leaves it alone until ~R5; the best player is free through R4
A13: Actress | B13: 37 | C13: 8 | D13: 0 / 1 / 5 | E13: 8.5 | F13: -0.5 | G13: 12.1 | H13: 12.1 | I13: 9.1 | J13: 7.3 | K13: 0 | L13: 3 | M13: 4.8 | N13: 2 | O13: TAKE BY R2: from R3 the best left drops 3+ pts below the top
... A16: Stock | B16: 158 | C16: 13 | D16: 0 / 0 / 0 | E16: 7 | F16: -1 | G16: 7.1 | H16: 7.1 | I16: 7.1 | J16: 7.1 | K16: 0 | L16: 0 | M16: 0 | N16: 14 | O16: COIN FLIP: take last, no edge
A18: How to read: assumes the field strips each category in order of 2027 EV at the pace it did in the 2025 draft (keeper round + snake). 'EV left @Rk' = best player still there after the 2026-style number of teams are gone by round k.
A19: Free until round = last round where the best player left is within 1 pt of the best on the board. WAIT = the field leaves the category alone; TAKE EARLY = it strips it fast.
A20: 2026 payoff: projected final = current points + projected remaining (MLS / NASCAR / MLB bonuses are not realised yet). Surplus = projected final minus the average pick in that round.
A21: Caveats: Country's 2026 surplus is the Olympics/World Cup bonus (13 pts) which does not exist in 2027. Musician surplus is the Feb-2026 Grammy bonus (repeats in Feb 2027). Per-pick surplus is mostly luck; category averages are the signal.
A22: The field does not draft by my EV order (it overweights Grammy/Oscar names), so Musician/Actor/Actress availability is approximate. Keepers may change who is already gone before round 1.

Sheet Draft Board
A1: Rank | B1: Category | C1: Candidate | D1: Owned by | E1: E[total] | F1: VOR | G1: Risk-adj VOR | H1: Tier in category | I1: Odds / price | J1: Detail | K1: Conf | L1: Source | M1: As of | N1: Plan | O1: Conf-adj VOR
A2: 1 | B2: Musician | C2: Ella Langley | D2: — free | E2: ='Musician'!M5 | F2: ='Musician'!N5 | G2: ='Musician'!O5 | H2: 1 | I2: Grammy EV 10.8 (raw 12.8, P(cap) 50%) | J2: 2026 raw 128; charting now: Choosin' Texas (#2); Be Her (#13); Loving Life Again (#16); carry-over 9.0 + new hits 8.9 (lambda 1.10, P(~0) 12%) | K2: C | L2: 2027 Hot 100 baseline = my estimate; Grammy: Kalshi KXGRAM*-69 prices (A) + estimates for other categories (C) | M2: 2026-10-08 | N2: Good but the field reaches for it: let it come to you | O2: ='Musician'!Y5
A3: 2 | B3: NBA | C3: Oklahoma City Thunder | D3: Feder | E3: ='NBA'!M5 | F3: ='NBA'!N5 | G3: ='NBA'!O5 | H3: 1 | I3: Kalshi 21.5% | J3: West; win total 62.5 | K3: A | L3: KXNBA-27 exchange mid-price, pulled 2026-10-08; p(final)=KXNBAEAST/KXNBAWEST-27 Kalshi mid | league_sim.py: full-schedule + real playoff bracket Monte Carlo, ratings fitted to Kalshi | M3: 2026-10-08 | O3: ='NBA'!Y5
A4: 3 | B4: NFL | C4: San Francisco 49ers | D4: Todd | E4: ='NFL'!M5 | F4: ='NFL'!N5 | G4: ='NFL'!O5 | H4: 1 | I4: Kalshi 9.5% | J4: 4-0, NFC West | K4: A | L4: KXSB-27 exchange mid-price, pulled 2026-10-08; p(final)=KXNFLAFCCHAMP/KXNFLNFCCHAMP-27 Kalshi mid | league_sim.py: full-schedule + real playoff bracket Monte Carlo, ratings fitted to Kalshi | M4: 2026-10-08 | O4: ='NFL'!Y5
A5: 4 | B5: NASCAR | C5: Kyle Larson | D5: Molmen | E5: ='NASCAR'!M5 | F5: ='NASCAR'!N5 | G5: ='NASCAR'!O5 | H5: 1 | I5: 2026 title: Kalshi 42.0% | J5: 2,318 pts, leads Chase after Las Vegas | K5: C | L5: User-supplied final Cup standings 2021-2026(proj.), recency-weighted (decay 0.65/yr, nascar_model.py) for drivers in the table; others = field prior blended with 2026 Kalshi title price (shrunk). No 2027 market exists. | M5: 2026-10-08 | N5: low confidence: far-out event | O5: ='NASCAR'!Y5
A6: 5 | B6: Musician | C6: Olivia Rodrigo | D6: Todd | E6: ='Musician'!M6 | F6: ='Musician'!N6 | G6: ='Musician'!O6 | H6: 1 | I6: Grammy EV 9.4 (raw 10.3, P(cap) 31%) | J6: 2026 raw 17; charting now: Drop Dead (#23); The Cure (#22); Stupid Song (#8); carry-over 6.1 + new hits 8.9 (lambda 1.10, P(~0) 17%) | K6: C | L6: 2027 Hot 100 baseline = my estimate; Grammy: Kalshi KXGRAM*-69 prices (A) + estimates for other categories (C) | M6: 2026-10-08 | N6: Good but the field reaches for it: let it come to you | O6: ='Musician'!Y6
A7: 6 | B7: NBA | C7: San Antonio Spurs | D7: Wu | E7: ='NBA'!M6 | F7: ='NBA'!N6 | G7: ='NBA'!O6 | H7: 1 | I7: Kalshi 21.5% | J7: West; win total 59.5 | K7: A | L7: KXNBA-27 exchange mid-price, pulled 2026-10-08; p(final)=KXNBAEAST/KXNBAWEST-27 Kalshi mid | league_sim.py: full-schedule + real playoff bracket Monte Carlo, ratings fitted to Kalshi | M7: 2026-10-08 | O7: ='NBA'!Y6
A8: 7 | B8: NCAAF | C8: Georgia | D8: Theo | E8: ='NCAAF'!M5 | F8: ='NCAAF'!N5 | G8: ='NCAAF'!O5 | H8: 1 | I8: Kalshi 16.5% | J8: AP #2, 5-0, SEC | K8: A | L8: KXNCAAF-27 exchange mid-price, pulled 2026-10-22 | M8: 2026-10-22 | O8: ='NCAAF'!Y5
A9: 8 | B9: NCAAB | C9: Florida | D9: Wu | E9: ='NCAAB'!M5 | F9: ='NCAAB'!N5 | G9: ='NCAAB'!O5 | H9: 1 | I9: +600 | K9: B | L9: CBS Sports title odds 2026-08-04 | M9: 2026-10-08 | N9: low confidence: far-out event | O9: ='NCAAB'!Y5
A10: 9 | B10: NCAAF | C10: Notre Dame | D10: Feder | E10: ='NCAAF'!M6 | F10: ='NCAAF'!N6 | G10: ='NCAAF'!O6 | H10: 1 | I10: Kalshi 12.5% | J10: AP #3, 5-0, Ind | K10: A | L10: KXNCAAF-27 exchange mid-price, pulled 2026-10-22 | M10: 2026-10-22 | O10: ='NCAAF'!Y6
A11: 10 | B11: NCAAF | C11: Miami (FL) | D11: Wu | E11: ='NCAAF'!M7 | F11: ='NCAAF'!N7 | G11: ='NCAAF'!O7 | H11: 1 | I11: Kalshi 14.5% | J11: AP #4, 5-0, ACC | K11: A | L11: KXNCAAF-27 exchange mid-price, pulled 2026-10-22 | M11: 2026-10-22 | O11: ='NCAAF'!Y7
A12: 11 | B12: NASCAR | C12: Denny Hamlin | D12: Theo | E12: ='NASCAR'!M6 | F12: ='NASCAR'!N6 | G12: ='NASCAR'!O6 | H12: 1 | I12: 2026 title: Kalshi 28.0% | J12: 2,278 pts (2nd) | K12: C | L12: User-supplied final Cup standings 2021-2026(proj.), recency-weighted (decay 0.65/yr, nascar_model.py) for drivers in the table; others = field prior blended with 2026 Kalshi title price (shrunk). No 2027 market exists. | M12: 2026-10-08 | N12: low confidence: far-out event | O12: ='NASCAR'!Y6
A13: 12 | B13: NCAAB | C13: Duke | D13: Jens | E13: ='NCAAB'!M6 | F13: ='NCAAB'!N6 | G13: ='NCAAB'!O6 | H13: 1 | I13: +600 | K13: B | L13: CBS Sports title odds 2026-08-04 | M13: 2026-10-08 | N13: low confidence: far-out event | O13: ='NCAAB'!Y6
A14: 13 | B14: NCAAF | C14: Ohio State | D14: Mitchell | E14: ='NCAAF'!M8 | F14: ='NCAAF'!N8 | G14: ='NCAAF'!O8 | H14: 2 | I14: Kalshi 12.5% | J14: AP #5, 4-1, Big Ten | K14: A | L14: KXNCAAF-27 exchange mid-price, pulled 2026-10-22 | M14: 2026-10-22 | O14: ='NCAAF'!Y8
A15: 14 | B15: Musician | C15: Olivia Dean | D15: — free | E15: ='Musician'!M7 | F15: ='Musician'!N7 | G15: ='Musician'!O7 | H15: 1 | I15: Grammy EV 8.5 (raw 9.2, P(cap) 23%) | J15: 2026 raw 61; charting now: none charting; carry-over 0.0 + new hits 9.0 (lambda 1.10, P(~0) 33%) | K15: C | L15: 2027 Hot 100 baseline = my estimate; Grammy: Kalshi KXGRAM*-69 prices (A) + estimates for other categories (C) | M15: 2026-10-08 | N15: Good but the field reaches for it: let it come to you | O15: ='Musician'!Y7
A16: 15 | B16: Country | C16: Iraq | D16: — free | E16: ='Country'!M5 | F16: ='Country'!N5 | G16: ='Country'!O5 | H16: 1 | I16: IMF Oct-2026 2027: 19.0% | J16: IMF Oct-2026: 2025 -0.414, 2026 -16.02, 2027 18.986 | war/rebound path: very wide forecast error | K16: A | L16: IMF World Economic Outlook, October 2026 (published 2026-10-13), api.imf.org SDMX dataflow IMF.RES/WEO NGDP_RPCH, pulled via Actions runner | M16: 2026-10-13 | O16: ='Country'!Y5
A17: 16 | B17: NFL | C17: Kansas City Chiefs | D17: Shep | E17: ='NFL'!M6 | F17: ='NFL'!N6 | G17: ='NFL'!O6 | H17: 1 | I17: Kalshi 9.5% | J17: 4-0, AFC West | K17: A | L17: KXSB-27 exchange mid-price, pulled 2026-10-08; p(final)=KXNFLAFCCHAMP/KXNFLNFCCHAMP-27 Kalshi mid | league_sim.py: full-schedule + real playoff bracket Monte Carlo, ratings fitted to Kalshi | M17: 2026-10-08 | O17: ='NFL'!Y6
A18: 17 | B18: Country | C18: Qatar | D18: — free | E18: ='Country'!M6 | F18: ='Country'!N6 | G18: ='Country'!O6 | H18: 1 | I18: IMF Oct-2026 2027: 18.8% | J18: IMF Oct-2026: 2025 1.808, 2026 -15.583, 2027 18.755 | war/rebound path: very wide forecast error | K18: A | L18: IMF World Economic Outlook, October 2026 (published 2026-10-13), api.imf.org SDMX dataflow IMF.RES/WEO NGDP_RPCH, pulled via Actions runner | M18: 2026-10-13 | O18: ='Country'!Y6
A19: 18 | B19: Actress | C19: Julianne Moore | D19: — free | E19: ='Actress'!M5 | F19: ='Actress'!N5 | G19: ='Actress'!O5 | H19: 1 | J19: no 2027 film found in Wikipedia's cast lists | K19: C | L19: Wikipedia 'List of American films of 2027' casts (Actions-runner pull 2026-10-08) x comp-based box office/RT estimates; cast lists are billed leads only (cameos not captured) | M19: 2026-10-08 | N19: Good but the field reaches for it: let it come to you | O19: ='Actress'!Y5
A20: 19 | B20: Tennis | C20: Jannik Sinner | D20: Buckley | E20: ='Tennis'!M5 | F20: ='Tennis'!N5 | G20: ='Tennis'!O5 | H20: 1 | I20: +100 AO 2027 (pre-injury) | J20: ATP 1 (2026-10-08) | K20: B | L20: ATP rank from league standings pull (A) / WTA via Olympics.com Oct 5; AO odds VegasInsider/Johnnybet Oct 2026; probabilities = agent estimates | M20: 2026-10-08 | O20: ='Tennis'!Y5
A21: 20 | B21: Musician | C21: Bruno Mars | D21: — free | E21: ='Musician'!M8 | F21: ='Musician'!N8 | G21: ='Musician'!O8 | H21: 2 | I21: Grammy EV 7.0 (raw 7.3, P(cap) 11%) | J21: 2026 raw 34; charting now: I Just Might (#11); Risk It All (#14); carry-over 2.9 + new hits 8.9 (lambda 1.10, P(~0) 24%) | K21: C | L21: 2027 Hot 100 baseline = my estimate; Grammy: Kalshi KXGRAM*-69 prices (A) + estimates for other categories (C) | M21: 2026-10-08 | N21: Good but the field reaches for it: let it come to you | O21: ='Musician'!Y8
A22: 21 | B22: Musician | C22: Taylor Swift | D22: Molmen | E22: ='Musician'!M9 | F22: ='Musician'!N9 | G22: ='Musician'!O9 | H22: 2 | I22: Grammy EV 7.4 (raw 7.7, P(cap) 13%) | J22: 2026 raw 61; charting now: Patient Zero (#1); carry-over 1.6 + new hits 8.8 (lambda 1.10, P(~0) 27%) | K22: C | L22: 2027 Hot 100 baseline = my estimate; Grammy: Kalshi KXGRAM*-69 prices (A) + estimates for other categories (C) | M22: 2026-10-08 | N22: Good but the field reaches for it: let it come to you | O22: ='Musician'!Y9
A23: 22 | B23: Country | C23: Guyana | D23: Korch | E23: ='Country'!M7 | F23: ='Country'!N7 | G23: ='Country'!O7 | H23: 1 | I23: IMF Oct-2026 2027: 16.8% | J23: IMF Oct-2026: 2025 19.31, 2026 22.325, 2027 16.789 | commodity-driven: wide forecast error | K23: A | L23: IMF World Economic Outlook, October 2026 (published 2026-10-13), api.imf.org SDMX dataflow IMF.RES/WEO NGDP_RPCH, pulled via Actions runner | M23: 2026-10-13 | O23: ='Country'!Y7
A24: 23 | B24: NFL | C24: Buffalo Bills | D24: Jens | E24: ='NFL'!M7 | F24: ='NFL'!N7 | G24: ='NFL'!O7 | H24: 1 | I24: Kalshi 10.5% | J24: 3-1, AFC East | K24: A | L24: KXSB-27 exchange mid-price, pulled 2026-10-08; p(final)=KXNFLAFCCHAMP/KXNFLNFCCHAMP-27 Kalshi mid | league_sim.py: full-schedule + real playoff bracket Monte Carlo, ratings fitted to Kalshi | M24: 2026-10-08 | O24: ='NFL'!Y7
A25: 24 | B25: NASCAR | C25: Christopher Bell | D25: Wu | E25: ='NASCAR'!M7 | F25: ='NASCAR'!N7 | G25: ='NASCAR'!O7 | H25: 1 | I25: 2026 title: Kalshi 10.5% | J25: 2,263 pts (3rd) | K25: C | L25: User-supplied final Cup standings 2021-2026(proj.), recency-weighted (decay 0.65/yr, nascar_model.py) for drivers in the table; others = field prior blended with 2026 Kalshi title price (shrunk). No 2027 market exists. | M25: 2026-10-08 | N25: low confidence: far-out event | O25: ='NASCAR'!Y7
A26: 25 | B26: NHL | C26: Carolina Hurricanes | D26: Jamzee | E26: ='NHL'!M5 | F26: ='NHL'!N5 | G26: ='NHL'!O5 | H26: 1 | I26: Kalshi 9.5% | J26: East | K26: A | L26: KXNHL-27 exchange mid-price, pulled 2026-10-08; p(final)=KXNHLEAST/KXNHLWEST-27 Kalshi mid | league_sim.py: full-schedule + real playoff bracket Monte Carlo, ratings fitted to Kalshi | M26: 2026-10-08 | O26: ='NHL'!Y5
A27: 26 | B27: Country | C27: Kuwait | D27: — free | E27: ='Country'!M8 | F27: ='Country'!N8 | G27: ='Country'!O8 | H27: 2 | I27: IMF Oct-2026 2027: 17.1% | J27: IMF Oct-2026: 2025 2.732, 2026 -16.74, 2027 17.125 | war/rebound path: very wide forecast error | K27: A | L27: IMF World Economic Outlook, October 2026 (published 2026-10-13), api.imf.org SDMX dataflow IMF.RES/WEO NGDP_RPCH, pulled via Actions runner | M27: 2026-10-13 | O27: ='Country'!Y8
A28: 27 | B28: NBA | C28: Philadelphia 76ers | D28: — free | E28: ='NBA'!M7 | F28: ='NBA'!N7 | G28: ='NBA'!O7 | H28: 1 | I28: Kalshi 12.5% | J28: East; win total 50.5 | K28: A | L28: KXNBA-27 exchange mid-price, pulled 2026-10-08; p(final)=KXNBAEAST/KXNBAWEST-27 Kalshi mid | league_sim.py: full-schedule + real playoff bracket Monte Carlo, ratings fitted to Kalshi | M28: 2026-10-08 | O28: ='NBA'!Y7
A29: 28 | B29: Tennis | C29: Elena Rybakina | D29: — free | E29: ='Tennis'!M6 | F29: ='Tennis'!N6 | G29: ='Tennis'!O6 | H29: 1 | I29: +300 AO 2027 | J29: WTA 1 (2026-10-08) | K29: B | L29: ATP rank from league standings pull (A) / WTA via Olympics.com Oct 5; AO odds VegasInsider/Johnnybet Oct 2026; probabilities = agent estimates | M29: 2026-10-08 | O29: ='Tennis'!Y6
A30: 29 | B30: NBA | C30: New York Knicks | D30: Buckley | E30: ='NBA'!M8 | F30: ='NBA'!N8 | G30: ='NBA'!O8 | H30: 2 | I30: Kalshi 8.5% | J30: East; win total 52.5 | K30: A | L30: KXNBA-27 exchange mid-price, pulled 2026-10-08; p(final)=KXNBAEAST/KXNBAWEST-27 Kalshi mid | league_sim.py: full-schedule + real playoff bracket Monte Carlo, ratings fitted to Kalshi | M30: 2026-10-08 | O30: ='NBA'!Y8
A31: 30 | B31: NHL | C31: Tampa Bay Lightning | D31: Fryar | E31: ='NHL'!M6 | F31: ='NHL'!N6 | G31: ='NHL'!O6 | H31: 1 | I31: Kalshi 5.5% | J31: East | K31: A | L31: KXNHL-27 exchange mid-price, pulled 2026-10-08; p(final)=KXNHLEAST/KXNHLWEST-27 Kalshi mid | league_sim.py: full-schedule + real playoff bracket Monte Carlo, ratings fitted to Kalshi | M31: 2026-10-08 | O31: ='NHL'!Y6
A32: 31 | B32: Tennis | C32: Aryna Sabalenka | D32: Fryar | E32: ='Tennis'!M7 | F32: ='Tennis'!N7 | G32: ='Tennis'!O7 | H32: 1 | I32: +175 to +185 AO 2027 | J32: WTA 2 (2026-10-08) | K32: B | L32: ATP rank from league standings pull (A) / WTA via Olympics.com Oct 5; AO odds VegasInsider/Johnnybet Oct 2026; probabilities = agent estimates | M32: 2026-10-08 | O32: ='Tennis'!Y7
A33: 32 | B33: Tennis | C33: Carlos Alcaraz | D33: Todd | E33: ='Tennis'!M8 | F33: ='Tennis'!N8 | G33: ='Tennis'!O8 | H33: 2 | I33: +150 AO 2027 | J33: ATP 3 (2026-10-08) | K33: B | L33: ATP rank from league standings pull (A) / WTA via Olympics.com Oct 5; AO odds VegasInsider/Johnnybet Oct 2026; probabilities = agent estimates | M33: 2026-10-08 | O33: ='Tennis'!Y8
A34: 33 | B34: Golf | C34: Scottie Scheffler | D34: Wu | E34: ='Golf'!M5 | F34: ='Golf'!N5 | G34: ='Golf'!O5 | H34: 1 | J34: OWGR 1 (2026-10-08) | K34: C | L34: OWGR rank from league standings pull (A); major-win probabilities = model (rank-weighted share of 4 majors) | M34: 2026-10-08 | O34: ='Golf'!Y5
A35: 34 | B35: NASCAR | C35: Joey Logano | D35: Jamzee | E35: ='NASCAR'!M8 | F35: ='NASCAR'!N8 | G35: ='NASCAR'!O8 | H35: 2 | I35: 2026 title: Kalshi 5.5% | J35: 2,247 pts (4th) | K35: C | L35: User-supplied final Cup standings 2021-2026(proj.), recency-weighted (decay 0.65/yr, nascar_model.py) for drivers in the table; others = field prior blended with 2026 Kalshi title price (shrunk). No 2027 market exists. | M35: 2026-10-08 | N35: low confidence: far-out event | O35: ='NASCAR'!Y8
A36: 35 | B36: NHL | C36: Edmonton Oilers | D36: Buckley | E36: ='NHL'!M7 | F36: ='NHL'!N7 | G36: ='NHL'!O7 | H36: 1 | I36: Kalshi 8.5% | J36: West | K36: A | L36: KXNHL-27 exchange mid-price, pulled 2026-10-08; p(final)=KXNHLEAST/KXNHLWEST-27 Kalshi mid | league_sim.py: full-schedule + real playoff bracket Monte Carlo, ratings fitted to Kalshi | M36: 2026-10-08 | O36: ='NHL'!Y7
A37: 36 | B37: Tennis | C37: Alexander Zverev | D37: Theo | E37: ='Tennis'!M9 | F37: ='Tennis'!N9 | G37: ='Tennis'!O9 | H37: 2 | I37: +700 AO 2027 | J37: ATP 2 (2026-10-08) | K37: B | L37: ATP rank from league standings pull (A) / WTA via Olympics.com Oct 5; AO odds VegasInsider/Johnnybet Oct 2026; probabilities = agent estimates | M37: 2026-10-08 | O37: ='Tennis'!Y9
A38: 37 | B38: NASCAR | C38: Ryan Blaney | D38: Fryar | E38: ='NASCAR'!M9 | F38: ='NASCAR'!N9 | G38: ='NASCAR'!O9 | H38: 2 | I38: 2026 title: Kalshi 5.5% | J38: 2,238 pts (5th) | K38: C | L38: User-supplied final Cup standings 2021-2026(proj.), recency-weighted (decay 0.65/yr, nascar_model.py) for drivers in the table; others = field prior blended with 2026 Kalshi title price (shrunk). No 2027 market exists. | M38: 2026-10-08 | N38: low confidence: far-out event | O38: ='NASCAR'!Y9
A39: 38 | B39: MLB | C39: Los Angeles Dodgers | D39: Wu | E39: ='MLB'!M5 | F39: ='MLB'!N5 | G39: ='MLB'!O5 | H39: 1 | J39: 2026: 100-62 (.6173) | K39: C | L39: 2026 win% from league standings (A); title prob = model estimate — no 2027 World Series odds posted | M39: 2026-10-08 | N39: low confidence: far-out event | O39: ='MLB'!Y5
A40: 39 | B40: Golf | C40: Rory McIlroy | D40: Molmen | E40: ='Golf'!M6 | F40: ='Golf'!N6 | G40: ='Golf'!O6 | H40: 1 | J40: OWGR 2 (2026-10-08) | K40: C | L40: OWGR rank from league standings pull (A); major-win probabilities = model (rank-weighted share of 4 majors) | M40: 2026-10-08 | O40: ='Golf'!Y6
...

Sheet Assumptions
A1: Category | B1: Champion | C1: Lost final | D1: Lost semi | E1: Lost quarter | F1: Lost round 1 | G1: Replacement rank N | H1: Bonus cap | I1: Replacement EV (Nth best / best left after the field's picks) | J1: Field award overweight w | K1: Field takes first M
A2: NFL | B2: 13 | C2: 9 | D2: 6.5 | E2: 4 | F2: 2.5 | G2: 7 | H2: 13 | I2: =LARGE('NFL'!$M$5:$M$36,MIN(G2,COUNT('NFL'!$M$5:$M$36)))
A3: NBA | B3: 13 | C3: 9 | D3: 6.5 | E3: 4 | F3: 2.5 | G3: 7 | H3: 13 | I3: =LARGE('NBA'!$M$5:$M$34,MIN(G3,COUNT('NBA'!$M$5:$M$34)))
A4: MLB | B4: 13 | C4: 9 | D4: 6.5 | E4: 4 | F4: 2.5 | G4: 7 | H4: 13 | I4: =LARGE('MLB'!$M$5:$M$34,MIN(G4,COUNT('MLB'!$M$5:$M$34)))
A5: NHL | B5: 13 | C5: 9 | D5: 6.5 | E5: 4 | F5: 2.5 | G5: 7 | H5: 13 | I5: =LARGE('NHL'!$M$5:$M$36,MIN(G5,COUNT('NHL'!$M$5:$M$36)))
A6: NCAAF | B6: 13 | C6: 9 | D6: 6.5 | E6: 4 | F6: 2.5 | G6: 7 | H6: 13 | I6: =LARGE('NCAAF'!$M$5:$M$32,MIN(G6,COUNT('NCAAF'!$M$5:$M$32)))
A7: NCAAB | B7: 13 | C7: 9 | D7: 6.5 | E7: 4 | F7: 2.5 | G7: 7 | H7: 13 | I7: =LARGE('NCAAB'!$M$5:$M$34,MIN(G7,COUNT('NCAAB'!$M$5:$M$34)))
A8: Tennis | G8: 7 | H8: 13 | I8: =LARGE('Tennis'!$M$5:$M$29,MIN(G8,COUNT('Tennis'!$M$5:$M$29)))
A9: Golf | G9: 7 | H9: 13 | I9: =LARGE('Golf'!$M$5:$M$44,MIN(G9,COUNT('Golf'!$M$5:$M$44)))
A10: NASCAR | G10: 7 | H10: 13 | I10: =LARGE('NASCAR'!$M$5:$M$28,MIN(G10,COUNT('NASCAR'!$M$5:$M$28)))
A11: MLS | B11: 13 | C11: 9 | D11: 6.5 | E11: 0 | F11: 0 | G11: 7 | H11: 13 | I11: =LARGE('MLS'!$M$5:$M$34,MIN(G11,COUNT('MLS'!$M$5:$M$34)))
A12: Actor | G12: 7 | H12: 13 | I12: =MAX(LARGE('Actor'!$M$5:$M$98,MIN(G12,COUNT('Actor'!$M$5:$M$98))),SUMPRODUCT(MAX(('Actor'!$W$5:$W$98>K12)*'Actor'!$M$5:$M$98))) | J12: 2 | K12: 8
A13: Actress | G13: 7 | H13: 13 | I13: =MAX(LARGE('Actress'!$M$5:$M$92,MIN(G13,COUNT('Actress'!$M$5:$M$92))),SUMPRODUCT(MAX(('Actress'!$W$5:$W$92>K13)*'Actress'!$M$5:$M$92))) | J13: 2 | K13: 8
A14: Musician | G14: 7 | H14: 13 | I14: =MAX(LARGE('Musician'!$M$5:$M$36,MIN(G14,COUNT('Musician'!$M$5:$M$36))),SUMPRODUCT(MAX(('Musician'!$W$5:$W$36>K14)*'Musician'!$M$5:$M$36))) | J14: 2 | K14: 8
A15: Country | G15: 7 | H15: 13 | I15: =LARGE('Country'!$M$5:$M$65,MIN(G15,COUNT('Country'!$M$5:$M$65)))
A16: Stock | G16: 7 | H16: 13 | I16: =LARGE('Stock'!$M$5:$M$30,MIN(G16,COUNT('Stock'!$M$5:$M$30)))
A19: Other inputs
A20: Tennis slam win pts | B20: 4
A21: Tennis slam runner-up pts | B21: 2.5
A22: Golf major win pts | B22: 6
A23: Golf major runner-up pts | B23: 2.5
A24: NASCAR avg pts for finishing 2nd-5th | B24: 4.5
A25: Risk aversion λ (Risk-adj VOR = VOR − λ·SD of rank pts) | B25: 0
A26: Confidence haircut, grade B (pts off VOR) | B26: 0.3
A27: Confidence haircut, grade C (pts off VOR) | B27: 0.8
A30: Certainty adjustments applied to data/*.json before the model (v2)
A31: Category | B31: sd multiplier | C31: mu shrink to field | D31: title-prob shrink to uniform | E31: Why
A32: NFL | B32: 1 | C32: 0 | D32: 0 | E32: season in progress, Kalshi-priced
A33: NBA | B33: 1 | C33: 0 | D33: 0 | E33: opens Oct 20, Kalshi-priced
A34: MLB | B34: 2 | C34: 0.5 | D34: 0.5 | E34: calendar 2027, no 2027 market; year-to-year win% persistence is weak
A35: NHL | B35: 1 | C35: 0 | D35: 0 | E35: season started, Kalshi-priced
A36: NCAAF | B36: 1 | C36: 0 | D36: 0 | E36: season in progress, Kalshi-priced
A37: NCAAB | B37: 1.6 | C37: 0.3 | D37: 0.25 | E37: season not started; tournament chaos
A38: Tennis | B38: 1 | C38: 0 | D38: 0 | E38: rankings sticky; slams stable at the top
A39: Golf | B39: 1 | C39: 0 | D39: 0 | E39: OWGR is sticky; majors are stable at the top
A40: NASCAR | B40: 2 | C40: 0.4 | D40: 0.3 | E40: calendar 2027, no 2027 market; probabilities now recency-weighted from 2021-26 final standings (lighter p shrink)
A41: MLS | B41: 2 | C41: 0.5 | D41: 0.5 | E41: calendar 2027, no 2027 market; playoff-driven
A42: Actor | B42: 1 | C42: 0 | D42: 0 | E42: see Market overweight
A43: Actress | B43: 1 | C43: 0 | D43: 0 | E43: see Market overweight
... A45: Country | B45: 1 | C45: 0 | D45: 0 | E45: IMF-published growth, small sd
...

Sheet NFL
A1: NFL — 2027 draft research (EV model; see README)
A2: As of 2026-10-22. Sorted by E[total]. Yellow = inferred / low-confidence (C).
A4: Candidate | B4: Detail | C4: Odds / price | D4: p(champ) | E4: p(final) | F4: p(semi) | G4: p(quarter) | H4: p(rd 1) | I4: mu | J4: sd | K4: E[rank pts] (MC) | L4: E[bonus] | M4: E[total] | N4: VOR | O4: Risk-adj VOR | P4: Tier | Q4: SD rank pts | R4: Source | S4: As of | T4: Conf | U4: Notes | V4: Field draft score | W4: Field rank | X4: Owner | Y4: Conf-adj VOR
A5: San Francisco 49ers | B5: 4-0, NFC West | C5: Kalshi 9.5% | D5: 0.142 | E5: 0.2631 | F5: 0.4592 | G5: 0.815 | H5: 0.97 | I5: 0.7361 | J5: 0.0948 | K5: 11.609 | L5: =Assumptions!$B$2*D5+Assumptions!$C$2*(E5-D5)+Assumptions!$D$2*(F5-E5)+Assumptions!$E$2*(G5-F5)+Assumptions!$F$2*(H5-G5) | M5: =K5+MIN(L5,Assumptions!$H$2) | N5: =M5-Assumptions!$I$2 | O5: =N5-Assumptions!$B$25*Q5 | P5: 1 | Q5: 2.1 | R5: KXSB-27 exchange mid-price, pulled 2026-10-08; p(final)=KXNFLAFCCHAMP/KXNFLNFCCHAMP-27 Kalshi mid | league_sim.py: full-schedule + real playoff bracket Monte Carlo, ratings fitted to Kalshi | S5: 2026-10-08 | T5: A | U5: [sim: playoffs 98%, rd2 82%, conf final 46%] | X5: Todd | Y5: =N5-IF(T5="C",Assumptions!$B$27,IF(T5="B",Assumptions!$B$26,0))
A6: Kansas City Chiefs | B6: 4-0, AFC West | C6: Kalshi 9.5% | D6: 0.0927 | E6: 0.1787 | F6: 0.3441 | G6: 0.6405 | H6: 0.9026 | I6: 0.6664 | J6: 0.1012 | K6: 9.906 | L6: =Assumptions!$B$2*D6+Assumptions!$C$2*(E6-D6)+Assumptions!$D$2*(F6-E6)+Assumptions!$E$2*(G6-F6)+Assumptions!$F$2*(H6-G6) | M6: =K6+MIN(L6,Assumptions!$H$2) | N6: =M6-Assumptions!$I$2 | O6: =N6-Assumptions!$B$25*Q6 | P6: 1 | Q6: 3.046 | R6: KXSB-27 exchange mid-price, pulled 2026-10-08; p(final)=KXNFLAFCCHAMP/KXNFLNFCCHAMP-27 Kalshi mid | league_sim.py: full-schedule + real playoff bracket Monte Carlo, ratings fitted to Kalshi | S6: 2026-10-08 | T6: A | U6: [sim: playoffs 90%, rd2 64%, conf final 34%] | X6: Shep | Y6: =N6-IF(T6="C",Assumptions!$B$27,IF(T6="B",Assumptions!$B$26,0))
A7: Buffalo Bills | B7: 3-1, AFC East | C7: Kalshi 10.5% | D7: 0.0931 | E7: 0.1829 | F7: 0.3331 | G7: 0.6 | H7: 0.883 | I7: 0.6488 | J7: 0.0977 | K7: 9.362 | L7: =Assumptions!$B$2*D7+Assumptions!$C$2*(E7-D7)+Assumptions!$D$2*(F7-E7)+Assumptions!$E$2*(G7-F7)+Assumptions!$F$2*(H7-G7) | M7: =K7+MIN(L7,Assumptions!$H$2) | N7: =M7-Assumptions!$I$2 | O7: =N7-Assumptions!$B$25*Q7 | P7: 1 | Q7: 3.148 | R7: KXSB-27 exchange mid-price, pulled 2026-10-08; p(final)=KXNFLAFCCHAMP/KXNFLNFCCHAMP-27 Kalshi mid | league_sim.py: full-schedule + real playoff bracket Monte Carlo, ratings fitted to Kalshi | S7: 2026-10-08 | T7: A | U7: lost to Patriots wk4 [sim: playoffs 88%, rd2 60%, conf final 33%] | X7: Jens | Y7: =N7-IF(T7="C",Assumptions!$B$27,IF(T7="B",Assumptions!$B$26,0))
A8: Minnesota Vikings | B8: 4-0, NFC North | C8: Kalshi 3.5% | D8: 0.0367 | E8: 0.0824 | F8: 0.2107 | G8: 0.4878 | H8: 0.8366 | I8: 0.634 | J8: 0.1012 | K8: 8.825 | L8: =Assumptions!$B$2*D8+Assumptions!$C$2*(E8-D8)+Assumptions!$D$2*(F8-E8)+Assumptions!$E$2*(G8-F8)+Assumptions!$F$2*(H8-G8) | M8: =K8+MIN(L8,Assumptions!$H$2) | N8: =M8-Assumptions!$I$2 | O8: =N8-Assumptions!$B$25*Q8 | P8: 2 | Q8: 3.329 | R8: KXSB-27 exchange mid-price, pulled 2026-10-08; p(final)=KXNFLAFCCHAMP/KXNFLNFCCHAMP-27 Kalshi mid | league_sim.py: full-schedule + real playoff bracket Monte Carlo, ratings fitted to Kalshi | S8: 2026-10-08 | T8: A | U8: [sim: playoffs 84%, rd2 49%, conf final 21%] | Y8: =N8-IF(T8="C",Assumptions!$B$27,IF(T8="B",Assumptions!$B$26,0))
A9: Baltimore Ravens | B9: 3-1, AFC North | C9: Kalshi 7.5% | D9: 0.065 | E9: 0.1229 | F9: 0.243 | G9: 0.4693 | H9: 0.7598 | I9: 0.6027 | J9: 0.0944 | K9: 7.878 | L9: =Assumptions!$B$2*D9+Assumptions!$C$2*(E9-D9)+Assumptions!$D$2*(F9-E9)+Assumptions!$E$2*(G9-F9)+Assumptions!$F$2*(H9-G9) | M9: =K9+MIN(L9,Assumptions!$H$2) | N9: =M9-Assumptions!$I$2 | O9: =N9-Assumptions!$B$25*Q9 | P9: 2 | Q9: 3.362 | R9: KXSB-27 exchange mid-price, pulled 2026-10-08; p(final)=KXNFLAFCCHAMP/KXNFLNFCCHAMP-27 Kalshi mid | league_sim.py: full-schedule + real playoff bracket Monte Carlo, ratings fitted to Kalshi | S9: 2026-10-08 | T9: A | U9: [sim: playoffs 76%, rd2 47%, conf final 24%] | X9: Wu | Y9: =N9-IF(T9="C",Assumptions!$B$27,IF(T9="B",Assumptions!$B$26,0))
A10: Jacksonville Jaguars | B10: 3-1, AFC South | C10: Kalshi 6.5% | D10: 0.0542 | E10: 0.1191 | F10: 0.2299 | G10: 0.4532 | H10: 0.7823 | I10: 0.5928 | J10: 0.0958 | K10: 7.572 | L10: =Assumptions!$B$2*D10+Assumptions!$C$2*(E10-D10)+Assumptions!$D$2*(F10-E10)+Assumptions!$E$2*(G10-F10)+Assumptions!$F$2*(H10-G10) | M10: =K10+MIN(L10,Assumptions!$H$2) | N10: =M10-Assumptions!$I$2 | O10: =N10-Assumptions!$B$25*Q10 | P10: 2 | Q10: 3.463 | R10: KXSB-27 exchange mid-price, pulled 2026-10-08; p(final)=KXNFLAFCCHAMP/KXNFLNFCCHAMP-27 Kalshi mid | league_sim.py: full-schedule + real playoff bracket Monte Carlo, ratings fitted to Kalshi | S10: 2026-10-08 | T10: A | U10: books disagree (+1100 to +2200) [sim: playoffs 78%, rd2 45%, conf final 23%] | Y10: =N10-IF(T10="C",Assumptions!$B$27,IF(T10="B",Assumptions!$B$26,0))
A11: Chicago Bears | B11: 3-1, NFC North | C11: Kalshi 4.5% | D11: 0.0656 | E11: 0.1239 | F11: 0.2376 | G11: 0.4333 | H11: 0.7029 | I11: 0.5829 | J11: 0.0971 | K11: 7.237 | L11: =Assumptions!$B$2*D11+Assumptions!$C$2*(E11-D11)+Assumptions!$D$2*(F11-E11)+Assumptions!$E$2*(G11-F11)+Assumptions!$F$2*(H11-G11) | M11: =K11+MIN(L11,Assumptions!$H$2) | N11: =M11-Assumptions!$I$2 | O11: =N11-Assumptions!$B$25*Q11 | P11: 2 | Q11: 3.466 | R11: KXSB-27 exchange mid-price, pulled 2026-10-08; p(final)=KXNFLAFCCHAMP/KXNFLNFCCHAMP-27 Kalshi mid | league_sim.py: full-schedule + real playoff bracket Monte Carlo, ratings fitted to Kalshi | S11: 2026-10-08 | T11: A | U11: [sim: playoffs 70%, rd2 43%, conf final 24%] | Y11: =N11-IF(T11="C",Assumptions!$B$27,IF(T11="B",Assumptions!$B$26,0))
A12: Denver Broncos | B12: 2-2, AFC West | C12: Kalshi 3.5% | D12: 0.0395 | E12: 0.0846 | F12: 0.1795 | G12: 0.3723 | H12: 0.685 | I12: 0.5797 | J12: 0.0965 | K12: 7.105 | L12: =Assumptions!$B$2*D12+Assumptions!$C$2*(E12-D12)+Assumptions!$D$2*(F12-E12)+Assumptions!$E$2*(G12-F12)+Assumptions!$F$2*(H12-G12) | M12: =K12+MIN(L12,Assumptions!$H$2) | N12: =M12-Assumptions!$I$2 | O12: =N12-Assumptions!$B$25*Q12 | P12: 3 | Q12: 3.462 | R12: KXSB-27 exchange mid-price, pulled 2026-10-08; p(final)=KXNFLAFCCHAMP/KXNFLNFCCHAMP-27 Kalshi mid | league_sim.py: full-schedule + real playoff bracket Monte Carlo, ratings fitted to Kalshi | S12: 2026-10-08 | T12: A | U12: [sim: playoffs 68%, rd2 37%, conf final 18%] | X12: Molmen | Y12: =N12-IF(T12="C",Assumptions!$B$27,IF(T12="B",Assumptions!$B$26,0))
A13: New England Patriots | B13: 2-2, AFC East | C13: Kalshi 2.5% | D13: 0.0478 | E13: 0.09 | F13: 0.1757 | G13: 0.351 | H13: 0.6252 | I13: 0.5619 | J13: 0.0973 | K13: 6.545 | L13: =Assumptions!$B$2*D13+Assumptions!$C$2*(E13-D13)+Assumptions!$D$2*(F13-E13)+Assumptions!$E$2*(G13-F13)+Assumptions!$F$2*(H13-G13) | M13: =K13+MIN(L13,Assumptions!$H$2) | N13: =M13-Assumptions!$I$2 | O13: =N13-Assumptions!$B$25*Q13 | P13: 3 | Q13: 3.45 | R13: KXSB-27 exchange mid-price, pulled 2026-10-08; p(final)=KXNFLAFCCHAMP/KXNFLNFCCHAMP-27 Kalshi mid | league_sim.py: full-schedule + real playoff bracket Monte Carlo, ratings fitted to Kalshi | S13: 2026-10-08 | T13: A | U13: beat Bills wk4 [sim: playoffs 63%, rd2 35%, conf final 18%] | X13: Feder | Y13: =N13-IF(T13="C",Assumptions!$B$27,IF(T13="B",Assumptions!$B$26,0))
A14: Cincinnati Bengals | B14: 2-2, AFC North | C14: Kalshi 3.5% | D14: 0.0345 | E14: 0.0729 | F14: 0.1661 | G14: 0.3374 | H14: 0.6204 | I14: 0.5644 | J14: 0.0997 | K14: 6.57 | L14: =Assumptions!$B$2*D14+Assumptions!$C$2*(E14-D14)+Assumptions!$D$2*(F14-E14)+Assumptions!$E$2*(G14-F14)+Assumptions!$F$2*(H14-G14) | M14: =K14+MIN(L14,Assumptions!$H$2) | N14: =M14-Assumptions!$I$2 | O14: =N14-Assumptions!$B$25*Q14 | P14: 3 | Q14: 3.522 | R14: KXSB-27 exchange mid-price, pulled 2026-10-08; p(final)=KXNFLAFCCHAMP/KXNFLNFCCHAMP-27 Kalshi mid | league_sim.py: full-schedule + real playoff bracket Monte Carlo, ratings fitted to Kalshi | S14: 2026-10-08 | T14: A | U14: [sim: playoffs 62%, rd2 34%, conf final 17%] | Y14: =N14-IF(T14="C",Assumptions!$B$27,IF(T14="B",Assumptions!$B$26,0))
A15: Detroit Lions | B15: 2-2, NFC North | C15: +3500 | D15: 0.0377 | E15: 0.0776 | F15: 0.161 | G15: 0.3395 | H15: 0.5926 | I15: 0.5574 | J15: 0.1009 | K15: 6.347 | L15: =Assumptions!$B$2*D15+Assumptions!$C$2*(E15-D15)+Assumptions!$D$2*(F15-E15)+Assumptions!$E$2*(G15-F15)+Assumptions!$F$2*(H15-G15) | M15: =K15+MIN(L15,Assumptions!$H$2) | N15: =M15-Assumptions!$I$2 | O15: =N15-Assumptions!$B$25*Q15 | P15: 3 | Q15: 3.493 | R15: estimate; p(final)=KXNFLAFCCHAMP/KXNFLNFCCHAMP-27 Kalshi mid | league_sim.py: full-schedule + real playoff bracket Monte Carlo, ratings fitted to Kalshi | S15: 2026-10-08 | T15: A | U15: [sim: playoffs 59%, rd2 34%, conf final 16%] | X15: Jamzee | Y15: =N15-IF(T15="C",Assumptions!$B$27,IF(T15="B",Assumptions!$B$26,0))
A16: Seattle Seahawks | B16: 3-1, NFC West | C16: Kalshi 8.5% | D16: 0.0553 | E16: 0.1055 | F16: 0.1918 | G16: 0.346 | H16: 0.5649 | I16: 0.5467 | J16: 0.0942 | K16: 5.96 | L16: =Assumptions!$B$2*D16+Assumptions!$C$2*(E16-D16)+Assumptions!$D$2*(F16-E16)+Assumptions!$E$2*(G16-F16)+Assumptions!$F$2*(H16-G16) | M16: =K16+MIN(L16,Assumptions!$H$2) | N16: =M16-Assumptions!$I$2 | O16: =N16-Assumptions!$B$25*Q16 | P16: 3 | Q16: 3.387 | R16: KXSB-27 exchange mid-price, pulled 2026-10-08; p(final)=KXNFLAFCCHAMP/KXNFLNFCCHAMP-27 Kalshi mid | league_sim.py: full-schedule + real playoff bracket Monte Carlo, ratings fitted to Kalshi | S16: 2026-10-08 | T16: A | U16: defending Super Bowl champion [sim: playoffs 56%, rd2 35%, conf final 19%] | X16: Tim | Y16: =N16-IF(T16="C",Assumptions!$B$27,IF(T16="B",Assumptions!$B$26,0))
A17: Green Bay Packers | B17: 2-2, NFC North | C17: +3500 | D17: 0.0285 | E17: 0.0624 | F17: 0.1389 | G17: 0.2916 | H17: 0.5489 | I17: 0.5448 | J17: 0.0962 | K17: 5.804 | L17: =Assumptions!$B$2*D17+Assumptions!$C$2*(E17-D17)+Assumptions!$D$2*(F17-E17)+Assumptions!$E$2*(G17-F17)+Assumptions!$F$2*(H17-G17) | M17: =K17+MIN(L17,Assumptions!$H$2) | N17: =M17-Assumptions!$I$2 | O17: =N17-Assumptions!$B$25*Q17 | P17: 3 | Q17: 3.419 | R17: estimate | league_sim.py: full-schedule + real playoff bracket Monte Carlo, ratings fitted to Kalshi | S17: 2026-10-08 | T17: A | U17: [sim: playoffs 55%, rd2 29%, conf final 14%] | X17: Fryar | Y17: =N17-IF(T17="C",Assumptions!$B$27,IF(T17="B",Assumptions!$B$26,0))
